Workbook

Sheet Instructions
A1: 🇵🇭 PHILIPPINE PAYROLL SYSTEM
A2: Supports up to 50 employees – User Guide
B3: SHEET INDEX
B4: 1. Instructions | C4: This guide – read first
B5: 2. Tax_Tables | C5: BIR TRAIN Law semi-monthly brackets
B6: 3. SSS_Table | C6: SSS contribution schedule (based on the latest 2025 onwards contribution table)
B7: 4. PhilHealth_Table | C7: PhilHealth premium schedule (2026 - latest)
B8: 5. PagIBIG_Table | C8: Pag-IBIG / HDMF contribution schedule (2026 based on employed members)
B9: 6. Employee_Master | C9: Employee database – up to 50 employees, Daily rate is based on a 5 working days per week, Hourly rate is based on 8 hours per 1 working day.
B10: 7. Payroll_Register | C10: Semi-monthly payroll for all active employees
B11: 8. Payslip | C11: Individual payslip – select employee from dropdown
B13: HOW TO ADD EMPLOYEES
B14: Step 1 | C14: Go to Employee_Master. Find the next empty row after the samples. | D14: *In case you have more than 50 employees you can just continue filling the next empty rows on the Employee_Master sheet and everything will be automatically updated.
B15: Step 2 | C15: Fill in ALL blue cells: Emp No, Name, Position, Dept, Status, Date Hired, Monthly Salary.
B16: Step 3 | C16: Daily Rate and Hourly Rate compute automatically.
B17: Step 4 | C17: Go to Payroll_Register. The new employee row is already there (pre-built for 50 rows).
B18: Step 5 | C18: All deductions and tax compute automatically once salary is in Employee_Master.
B19: Step 6 | C19: For Payslip, choose the employee from the dropdown (row numbers 6–55).
B21: COLOR LEGEND
B22: 🔵 Blue text | C22: Hard-coded inputs – cells you fill in
B23: ⚫ Black text | C23: Formula cells – do not edit
B24: 🟢 Green text | C24: Cross-sheet references
B26: LEGAL NOTES
B27: SSS | C27: R.A. 11199 – Social Security Act of 2018 - Circular 2024-006
B28: PhilHealth | C28: R.A. 11223 – 5% rate (2.5% EE share) effective 2026
B29: Pag-IBIG | C29: R.A. 9679 – max employee contribution ₱200/month - effective 2026
B30: Withholding Tax | C30: TRAIN Law R.A. 10963 – semi-monthly brackets
B31: 13th Month | C31: P.D. 851 – mandatory for rank-and-file
B32: DISCLAIMER | C32: Always verify current rates with BIR, SSS, PhilHealth, Pag-IBIG.

Sheet Tax_Tables
A1: BIR WITHHOLDING TAX TABLE – Semi-Monthly (TRAIN Law)
A2: Effective Jan 1 2023 | R.A. 10963
B3: From (₱) | C3: To (₱) | D3: Base Tax (₱) | E3: Rate on Excess | F3: Excess Over (₱) | G3: Notes
A4: 1 | B4: 0 | C4: 10417 | D4: 0 | E4: 0 | F4: 0 | G4: Tax exempt
A5: 2 | B5: 10417 | C5: 16666 | D5: 0 | E5: 0.15 | F5: 10417 | G5: 15% of excess
A6: 3 | B6: 16667 | C6: 33332 | D6: 937.5 | E6: 0.2 | F6: 16667 | G6: ₱937.50 + 20% of excess
A7: 4 | B7: 33333 | C7: 83332 | D7: 4270.7 | E7: 0.25 | F7: 33333 | G7: ₱4270.70 + 25% of excess
A8: 5 | B8: 83333 | C8: 333332 | D8: 16770.7 | E8: 0.3 | F8: 83333 | G8: ₱16770.70 + 30% of excess
A9: 6 | B9: 333333 | C9: Above | D9: 91770.7 | E9: 0.35 | F9: 333333 | G9: ₱91770.70 + 35% of excess

Sheet SSS_Table
A1: SSS CONTRIBUTION TABLE (2023)
A2: SSS Circular 2023-002
B3: Range From (₱) | C3: Range To (₱) | D3: EE Share (₱) | E3: ER Share (₱) | F3: Total (₱) | G3: MSC (₱)
A4: 1 | B4: 1 | C4: 5249.99 | D4: 250 | E4: 510 | F4: 760 | G4: 5000
A5: 2 | B5: 5250 | C5: 5749.99 | D5: 275 | E5: 560 | F5: 835 | G5: 5500
A6: 3 | B6: 5750 | C6: 6249.99 | D6: 300 | E6: 610 | F6: 910 | G6: 6000
A7: 4 | B7: 6250 | C7: 6749.99 | D7: 325 | E7: 660 | F7: 985 | G7: 6500
A8: 5 | B8: 6750 | C8: 7249.99 | D8: 350 | E8: 710 | F8: 1060 | G8: 7000
A9: 6 | B9: 7250 | C9: 7749.99 | D9: 375 | E9: 760 | F9: 1135 | G9: 7500
A10: 7 | B10: 7750 | C10: 8249.99 | D10: 400 | E10: 810 | F10: 1210 | G10: 8000
A11: 8 | B11: 8250 | C11: 8749.99 | D11: 425 | E11: 860 | F11: 1285 | G11: 8500
A12: 9 | B12: 8750 | C12: 9249.99 | D12: 450 | E12: 910 | F12: 1360 | G12: 9000
A13: 10 | B13: 9250 | C13: 9749.99 | D13: 475 | E13: 960 | F13: 1435 | G13: 9500
A14: 11 | B14: 9750 | C14: 10249.99 | D14: 500 | E14: 1010 | F14: 1510 | G14: 10000
A15: 12 | B15: 10250 | C15: 10749.99 | D15: 525 | E15: 1060 | F15: 1585 | G15: 10500
... A64: 61 | B64: 34750 | C64: 100000000 | D64: 1750 | E64: 3530 | F64: 5280 | G64: 35000

Sheet PhilHealth_Table
A1: PHILHEALTH PREMIUM TABLE (2024)
A2: PhilHealth Circular 2023-0009 | Rate: 5% (EE: 2.5%, ER: 2.5%)
B3: From (₱) | C3: To (₱) | D3: EE Share | E3: ER Share | F3: Notes
A4: 1 | B4: 0 | C4: 9999.99 | D4: MIN ₱250.00 | E4: MIN ₱250.00 | F4: Minimum monthly: ₱500 total
A5: 2 | B5: 10000 | C5: 99999.99 | D5: Basic × 2.5% | E5: Basic × 2.5% | F5: Rate applied on monthly basic salary
A6: 3 | B6: 100000 | C6: 9999999 | D6: MAX ₱2,500 | E6: MAX ₱2,500 | F6: Maximum monthly: ₱5,000 total (cap ₱100K)
B8: Formula: =MIN(MAX(BasicSalary×0.025,137.50),1375) per month. Divide by 2 for semi-monthly.

Sheet PagIBIG_Table
A1: PAG-IBIG / HDMF CONTRIBUTION TABLE
A2: HDMF Circular 2021-009 | Max employee contribution: ₱200/month
B3: From (₱) | C3: To (₱) | D3: EE Rate | E3: ER Rate | F3: Notes
A4: 1 | B4: 1 | C4: 1499.99 | D4: 1% | E4: 2% | F4: 1% of monthly comp
A5: 2 | B5: 1500 | C5: 9999999 | D5: 2% | E5: 2% | F5: 2%; EE max ₱200/month
B7: Formula: =MIN(MonthlySalary×0.02,200)/2 for semi-monthly employee share.

Sheet Holiday_Schedule
B1: 🇵🇭 PHILIPPINE HOLIDAY SCHEDULE & PAY RULES
B2: Per Labor Code & DOLE | Regular Holiday=200% | Special Non-Working=+30% premium
B4: HOLIDAY PAY COMPUTATION RULES (Labor Code of the Philippines)
B5: Regular Holiday – Employee WORKS | C5: Daily Rate × 200% | D5: Full day + 100% premium
B6: Regular Holiday – Employee does NOT work | C6: Daily Rate × 100% | D6: Entitled even if absent
B7: Special Non-Working – Employee WORKS | C7: Daily Rate × 130% | D7: Basic + 30% premium
B8: Special Non-Working – Does NOT work | C8: No pay | D8: No work, no pay rule
B9: Regular Holiday on rest day + works | C9: Daily Rate × 260% | D9: 200% + 30% rest day premium
B10: Special Holiday on rest day + works | C10: Daily Rate × 150% | D10: 130% + 50% rest day premium
B12: 2025 OFFICIAL HOLIDAY LIST (Update dates annually)
B13: Holiday Name | C13: Date (YYYY-MM-DD) | D13: Type | E13: Pay Multiplier
B14: New Year's Day | C14: 2025-01-01 | D14: Regular Holiday | E14: 2
B15: EDSA People Power Revolution | C15: 2025-02-25 | D15: Special Non-Working | E15: 1.3
B16: Araw ng Kagitingan | C16: 2025-04-09 | D16: Regular Holiday | E16: 2
B17: Maundy Thursday | C17: 2025-04-17 | D17: Regular Holiday | E17: 2
B18: Good Friday | C18: 2025-04-18 | D18: Regular Holiday | E18: 2
B19: Black Saturday | C19: 2025-04-19 | D19: Special Non-Working | E19: 1.3
B20: Eid'l Fitr (tentative) | C20: 2025-03-31 | D20: Regular Holiday | E20: 2
B21: Labor Day | C21: 2025-05-01 | D21: Regular Holiday | E21: 2
B22: Eid'l Adha (tentative) | C22: 2025-06-07 | D22: Regular Holiday | E22: 2
B23: Independence Day | C23: 2025-06-12 | D23: Regular Holiday | E23: 2
B24: National Heroes Day | C24: 2025-08-25 | D24: Regular Holiday | E24: 2
B25: Ninoy Aquino Day | C25: 2025-08-21 | D25: Special Non-Working | E25: 1.3
... B33: Last Day of Year | C33: 2025-12-31 | D33: Special Non-Working | E33: 1.3
B35: 🟡 Regular Holiday (200%) 🔵 Special Non-Working (130%) Enter days worked in Payroll_Register cols R & T.

Sheet Employee_Master
A1: EMPLOYEE MASTER LIST
A2: Supports up to 50 employees – fill blue cells only
B3: Emp No. | C3: Full Name | D3: Position | E3: Department | F3: Employment Status | G3: Date Hired | H3: Monthly Basic Salary (₱) | I3: Daily Rate (₱) | J3: Hourly Rate (₱) | K3: SSS No. | L3: PhilHealth No. | M3: TIN | N3: Pag-IBIG MID | O3: Tax Status | P3: Pay Frequency
A4: 1 | B4: EMP-001 | C4: Juan dela Cruz | D4: Accountant | E4: Finance | F4: Regular | G4: 2020-01-15 | H4: 30000 | I4: =IFERROR(H4/22,"") -> 1363.6364 | J4: =IFERROR(I4/8,"") -> 170.45455 | O4: ME | P4: Semi-Monthly
A5: 2 | B5: EMP-002 | C5: Maria Santos | D5: HR Officer | E5: HR | F5: Regular | G5: 2021-03-01 | H5: 25000 | I5: =IFERROR(H5/22,"") -> 1136.3636 | J5: =IFERROR(I5/8,"") -> 142.04545 | O5: ME | P5: Semi-Monthly
A6: 3 | B6: EMP-003 | C6: Pedro Reyes | D6: IT Specialist | E6: IT | F6: Regular | G6: 2022-06-01 | H6: 35000 | I6: =IFERROR(H6/22,"") -> 1590.9091 | J6: =IFERROR(I6/8,"") -> 198.86364 | O6: ME | P6: Semi-Monthly
A7: 4 | B7: EMP-004 | C7: Ana Gonzales | D7: Sales Associate | E7: Sales | F7: Probationary | G7: 2024-01-01 | H7: 18000 | I7: =IFERROR(H7/22,"") -> 818.18182 | J7: =IFERROR(I7/8,"") -> 102.27273 | O7: ME | P7: Semi-Monthly
A8: 5 | B8: EMP-005 | C8: Jose Bautista | D8: Driver | E8: Operations | F8: Regular | G8: 2019-07-01 | H8: 16000 | I8: =IFERROR(H8/22,"") -> 727.27273 | J8: =IFERROR(I8/8,"") -> 90.909091 | O8: ME | P8: Semi-Monthly
A9: 6 | B9: EMP-006 | I9: =IFERROR(H9/22,"") -> 0 | J9: =IFERROR(I9/8,"") -> 0
A10: 7 | B10: EMP-007 | I10: =IFERROR(H10/22,"") -> 0 | J10: =IFERROR(I10/8,"") -> 0
A11: 8 | B11: EMP-008 | I11: =IFERROR(H11/22,"") -> 0 | J11: =IFERROR(I11/8,"") -> 0
A12: 9 | B12: EMP-009 | I12: =IFERROR(H12/22,"") -> 0 | J12: =IFERROR(I12/8,"") -> 0
A13: 10 | B13: EMP-010 | I13: =IFERROR(H13/22,"") -> 0 | J13: =IFERROR(I13/8,"") -> 0
A14: 11 | B14: EMP-011 | I14: =IFERROR(H14/22,"") -> 0 | J14: =IFERROR(I14/8,"") -> 0
A15: 12 | B15: EMP-012 | I15: =IFERROR(H15/22,"") -> 0 | J15: =IFERROR(I15/8,"") -> 0
A16: 13 | B16: EMP-013 | I16: =IFERROR(H16/22,"") -> 0 | J16: =IFERROR(I16/8,"") -> 0
A17: 14 | B17: EMP-014 | I17: =IFERROR(H17/22,"") -> 0 | J17: =IFERROR(I17/8,"") -> 0
A18: 15 | B18: EMP-015 | I18: =IFERROR(H18/22,"") -> 0 | J18: =IFERROR(I18/8,"") -> 0
A19: 16 | B19: EMP-016 | I19: =IFERROR(H19/22,"") -> 0 | J19: =IFERROR(I19/8,"") -> 0
A20: 17 | B20: EMP-017 | I20: =IFERROR(H20/22,"") -> 0 | J20: =IFERROR(I20/8,"") -> 0
... A53: 50 | B53: EMP-050 | I53: =IFERROR(H53/22,"") -> 0 | J53: =IFERROR(I53/8,"") -> 0

Sheet Attendance_Register
B1: 📋 ATTENDANCE REGISTER — Philippine Payroll System
B2: Blue cells = input. Attendance totals auto-scale to the employee's Pay Frequency set in Employee_Master. Deductions flow automatically to Payroll_Register col J (Absences/Late).
B3: Period: | C3: =Payroll_Register!C3 -> 1st Half | D3: Month: | E3: =Payroll_Register!E3 -> January | F3: Year: | G3: =Payroll_Register!G3 -> 2024
B4: Std Working Days/Period: | E4: See col D per employee → | H4: Standard days: Weekly=5 | Semi-Monthly=11 | Monthly=22 | Deductions use Daily Rate from Employee_Master col I.
B5: EMPLOYEE INFO | E5: ABSENCES (Days) | H5: LEAVES (Days) | K5: LATE / UNDERTIME | M5: PERIOD SUMMARY | O5: DEDUCTIONS (₱) | Q5: NET DEDUCTION → PR
B6: # | C6: Employee Name | D6: Pay Freq / Std Days | E6: Unexcused Absent (Days) | F6: AWOL (Days) | G6: Absent w/o Pay (Days) | H6: Sick Leave w/ Pay (Days) | I6: Vacation Leave (Days) | J6: Other Leave (Days) | K6: Late (Hours) | L6: Undertime (Hours) | M6: Total Absent Days | N6: Total Late/UT (Hours) | O6: Absence Deduction (₱) | P6: Late/UT Deduction (₱) | Q6: Total Deduction → PR (₱)
B7: 1 | C7: =IFERROR(Employee_Master!C4,"") -> Juan dela Cruz | D7: =IFERROR(IF(Employee_Master!P4="","—",Employee_Master!P4&" ("&IF(IFERROR(Employee_Master!P4,"")="Weekly",5,IF(IFERROR(Employee_Master!P4,"")="Monthly",22,11))&" days)"),"—") -> Semi-Monthly (11 days) | E7: 0 | F7: 0 | G7: 0 | H7: 0 | I7: 0 | J7: 0 | K7: 0 | L7: 0 | M7: =IFERROR(E7+F7+G7,0) -> 0 | N7: =IFERROR(K7+L7,0) -> 0 | O7: =IFERROR(M7*IFERROR(Employee_Master!I4,0),0) -> 0 | P7: =IFERROR(N7*IFERROR(Employee_Master!J4,0),0) -> 0 | Q7: =IFERROR(O7+P7,0) -> 0
B8: 2 | C8: =IFERROR(Employee_Master!C5,"") -> Maria Santos | D8: =IFERROR(IF(Employee_Master!P5="","—",Employee_Master!P5&" ("&IF(IFERROR(Employee_Master!P5,"")="Weekly",5,IF(IFERROR(Employee_Master!P5,"")="Monthly",22,11))&" days)"),"—") -> Semi-Monthly (11 days) | E8: 0 | F8: 0 | G8: 0 | H8: 0 | I8: 0 | J8: 0 | K8: 0 | L8: 0 | M8: =IFERROR(E8+F8+G8,0) -> 0 | N8: =IFERROR(K8+L8,0) -> 0 | O8: =IFERROR(M8*IFERROR(Employee_Master!I5,0),0) -> 0 | P8: =IFERROR(N8*IFERROR(Employee_Master!J5,0),0) -> 0 | Q8: =IFERROR(O8+P8,0) -> 0
B9: 3 | C9: =IFERROR(Employee_Master!C6,"") -> Pedro Reyes | D9: =IFERROR(IF(Employee_Master!P6="","—",Employee_Master!P6&" ("&IF(IFERROR(Employee_Master!P6,"")="Weekly",5,IF(IFERROR(Employee_Master!P6,"")="Monthly",22,11))&" days)"),"—") -> Semi-Monthly (11 days) | E9: 0 | F9: 0 | G9: 0 | H9: 0 | I9: 0 | J9: 0 | K9: 0 | L9: 0 | M9: =IFERROR(E9+F9+G9,0) -> 0 | N9: =IFERROR(K9+L9,0) -> 0 | O9: =IFERROR(M9*IFERROR(Employee_Master!I6,0),0) -> 0 | P9: =IFERROR(N9*IFERROR(Employee_Master!J6,0),0) -> 0 | Q9: =IFERROR(O9+P9,0) -> 0
B10: 4 | C10: =IFERROR(Employee_Master!C7,"") -> Ana Gonzales | D10: =IFERROR(IF(Employee_Master!P7="","—",Employee_Master!P7&" ("&IF(IFERROR(Employee_Master!P7,"")="Weekly",5,IF(IFERROR(Employee_Master!P7,"")="Monthly",22,11))&" days)"),"—") -> Semi-Monthly (11 days) | E10: 0 | F10: 0 | G10: 0 | H10: 0 | I10: 0 | J10: 0 | K10: 0 | L10: 0 | M10: =IFERROR(E10+F10+G10,0) -> 0 | N10: =IFERROR(K10+L10,0) -> 0 | O10: =IFERROR(M10*IFERROR(Employee_Master!I7,0),0) -> 0 | P10: =IFERROR(N10*IFERROR(Employee_Master!J7,0),0) -> 0 | Q10: =IFERROR(O10+P10,0) -> 0
B11: 5 | C11: =IFERROR(Employee_Master!C8,"") -> Jose Bautista | D11: =IFERROR(IF(Employee_Master!P8="","—",Employee_Master!P8&" ("&IF(IFERROR(Employee_Master!P8,"")="Weekly",5,IF(IFERROR(Employee_Master!P8,"")="Monthly",22,11))&" days)"),"—") -> Semi-Monthly (11 days) | E11: 0 | F11: 0 | G11: 0 | H11: 0 | I11: 0 | J11: 0 | K11: 0 | L11: 0 | M11: =IFERROR(E11+F11+G11,0) -> 0 | N11: =IFERROR(K11+L11,0) -> 0 | O11: =IFERROR(M11*IFERROR(Employee_Master!I8,0),0) -> 0 | P11: =IFERROR(N11*IFERROR(Employee_Master!J8,0),0) -> 0 | Q11: =IFERROR(O11+P11,0) -> 0
B12: 6 | C12: =IFERROR(Employee_Master!C9,"") -> 0 | D12: =IFERROR(IF(Employee_Master!P9="","—",Employee_Master!P9&" ("&IF(IFERROR(Employee_Master!P9,"")="Weekly",5,IF(IFERROR(Employee_Master!P9,"")="Monthly",22,11))&" days)"),"—") -> — | E12: 0 | F12: 0 | G12: 0 | H12: 0 | I12: 0 | J12: 0 | K12: 0 | L12: 0 | M12: =IFERROR(E12+F12+G12,0) -> 0 | N12: =IFERROR(K12+L12,0) -> 0 | O12: =IFERROR(M12*IFERROR(Employee_Master!I9,0),0) -> 0 | P12: =IFERROR(N12*IFERROR(Employee_Master!J9,0),0) -> 0 | Q12: =IFERROR(O12+P12,0) -> 0
B13: 7 | C13: =IFERROR(Employee_Master!C10,"") -> 0 | D13: =IFERROR(IF(Employee_Master!P10="","—",Employee_Master!P10&" ("&IF(IFERROR(Employee_Master!P10,"")="Weekly",5,IF(IFERROR(Employee_Master!P10,"")="Monthly",22,11))&" days)"),"—") -> — | E13: 0 | F13: 0 | G13: 0 | H13: 0 | I13: 0 | J13: 0 | K13: 0 | L13: 0 | M13: =IFERROR(E13+F13+G13,0) -> 0 | N13: =IFERROR(K13+L13,0) -> 0 | O13: =IFERROR(M13*IFERROR(Employee_Master!I10,0),0) -> 0 | P13: =IFERROR(N13*IFERROR(Employee_Master!J10,0),0) -> 0 | Q13: =IFERROR(O13+P13,0) -> 0
B14: 8 | C14: =IFERROR(Employee_Master!C11,"") -> 0 | D14: =IFERROR(IF(Employee_Master!P11="","—",Employee_Master!P11&" ("&IF(IFERROR(Employee_Master!P11,"")="Weekly",5,IF(IFERROR(Employee_Master!P11,"")="Monthly",22,11))&" days)"),"—") -> — | E14: 0 | F14: 0 | G14: 0 | H14: 0 | I14: 0 | J14: 0 | K14: 0 | L14: 0 | M14: =IFERROR(E14+F14+G14,0) -> 0 | N14: =IFERROR(K14+L14,0) -> 0 | O14: =IFERROR(M14*IFERROR(Employee_Master!I11,0),0) -> 0 | P14: =IFERROR(N14*IFERROR(Employee_Master!J11,0),0) -> 0 | Q14: =IFERROR(O14+P14,0) -> 0
B15: 9 | C15: =IFERROR(Employee_Master!C12,"") -> 0 | D15: =IFERROR(IF(Employee_Master!P12="","—",Employee_Master!P12&" ("&IF(IFERROR(Employee_Master!P12,"")="Weekly",5,IF(IFERROR(Employee_Master!P12,"")="Monthly",22,11))&" days)"),"—") -> — | E15: 0 | F15: 0 | G15: 0 | H15: 0 | I15: 0 | J15: 0 | K15: 0 | L15: 0 | M15: =IFERROR(E15+F15+G15,0) -> 0 | N15: =IFERROR(K15+L15,0) -> 0 | O15: =IFERROR(M15*IFERROR(Employee_Master!I12,0),0) -> 0 | P15: =IFERROR(N15*IFERROR(Employee_Master!J12,0),0) -> 0 | Q15: =IFERROR(O15+P15,0) -> 0
B16: 10 | C16: =IFERROR(Employee_Master!C13,"") -> 0 | D16: =IFERROR(IF(Employee_Master!P13="","—",Employee_Master!P13&" ("&IF(IFERROR(Employee_Master!P13,"")="Weekly",5,IF(IFERROR(Employee_Master!P13,"")="Monthly",22,11))&" days)"),"—") -> — | E16: 0 | F16: 0 | G16: 0 | H16: 0 | I16: 0 | J16: 0 | K16: 0 | L16: 0 | M16: =IFERROR(E16+F16+G16,0) -> 0 | N16: =IFERROR(K16+L16,0) -> 0 | O16: =IFERROR(M16*IFERROR(Employee_Master!I13,0),0) -> 0 | P16: =IFERROR(N16*IFERROR(Employee_Master!J13,0),0) -> 0 | Q16: =IFERROR(O16+P16,0) -> 0
B17: 11 | C17: =IFERROR(Employee_Master!C14,"") -> 0 | D17: =IFERROR(IF(Employee_Master!P14="","—",Employee_Master!P14&" ("&IF(IFERROR(Employee_Master!P14,"")="Weekly",5,IF(IFERROR(Employee_Master!P14,"")="Monthly",22,11))&" days)"),"—") -> — | E17: 0 | F17: 0 | G17: 0 | H17: 0 | I17: 0 | J17: 0 | K17: 0 | L17: 0 | M17: =IFERROR(E17+F17+G17,0) -> 0 | N17: =IFERROR(K17+L17,0) -> 0 | O17: =IFERROR(M17*IFERROR(Employee_Master!I14,0),0) -> 0 | P17: =IFERROR(N17*IFERROR(Employee_Master!J14,0),0) -> 0 | Q17: =IFERROR(O17+P17,0) -> 0
B18: 12 | C18: =IFERROR(Employee_Master!C15,"") -> 0 | D18: =IFERROR(IF(Employee_Master!P15="","—",Employee_Master!P15&" ("&IF(IFERROR(Employee_Master!P15,"")="Weekly",5,IF(IFERROR(Employee_Master!P15,"")="Monthly",22,11))&" days)"),"—") -> — | E18: 0 | F18: 0 | G18: 0 | H18: 0 | I18: 0 | J18: 0 | K18: 0 | L18: 0 | M18: =IFERROR(E18+F18+G18,0) -> 0 | N18: =IFERROR(K18+L18,0) -> 0 | O18: =IFERROR(M18*IFERROR(Employee_Master!I15,0),0) -> 0 | P18: =IFERROR(N18*IFERROR(Employee_Master!J15,0),0) -> 0 | Q18: =IFERROR(O18+P18,0) -> 0
... B56: 50 | C56: =IFERROR(Employee_Master!C53,"") -> 0 | D56: =IFERROR(IF(Employee_Master!P53="","—",Employee_Master!P53&" ("&IF(IFERROR(Employee_Master!P53,"")="Weekly",5,IF(IFERROR(Employee_Master!P53,"")="Monthly",22,11))&" days)"),"—") -> — | E56: 0 | F56: 0 | G56: 0 | H56: 0 | I56: 0 | J56: 0 | K56: 0 | L56: 0 | M56: =IFERROR(E56+F56+G56,0) -> 0 | N56: =IFERROR(K56+L56,0) -> 0 | O56: =IFERROR(M56*IFERROR(Employee_Master!I53,0),0) -> 0 | P56: =IFERROR(N56*IFERROR(Employee_Master!J53,0),0) -> 0 | Q56: =IFERROR(O56+P56,0) -> 0
B57: PERIOD TOTALS | E57: =SUM(E7:E56) -> 0 | F57: =SUM(F7:F56) -> 0 | G57: =SUM(G7:G56) -> 0 | H57: =SUM(H7:H56) -> 0 | I57: =SUM(I7:I56) -> 0 | J57: =SUM(J7:J56) -> 0 | K57: =SUM(K7:K56) -> 0 | L57: =SUM(L7:L56) -> 0 | ... Q57: =SUM(Q7:Q56) -> 0
B59: 📘 NOTES: Absent w/ Pay (sick/vacation leaves) do NOT trigger a deduction — only unexcused, AWOL & absent w/o pay days are deducted. | Late/Undertime uses Hourly Rate from Employee_Master. | Col Q (Total Deduction) flows automatically into Payroll_Register col J (Absences/Late ₱).

Sheet Payroll_Register
A1: PAYROLL REGISTER
A2: Company Name: | D2: [Enter Company Name]
A3: Payroll Period: | C3: 1st Half | D3: Month: | E3: January | F3: Year: | G3: 2024 | H3: Working Days: | I3: 13 | J3: Deduct Mandatory: | K3: Every Period | L3: ← Semi-monthly only. 'Every Period' applies to weekly & monthly.
D4: EARNINGS | G4: MANDATORY DEDUCTIONS (EE Share) | J4: OTHER DEDUCTIONS | L4: GROSS / TAX / NET | P4: OTHER | R4: HOLIDAY PAY | V4: EMPLOYER CONTRIBUTIONS | W4: EMPLOYER CONTRIBUTIONS
A5: # | B5: Emp No. | C5: Employee Name | D5: Basic Salary (Monthly ₱) | E5: Days Worked | F5: Basic Pay (₱) | G5: SSS (₱) | H5: PhilHealth (₱) | I5: Pag-IBIG (₱) | J5: Absences/ Late (₱) | K5: Loans & Other (₱) | L5: Gross Pay (₱) | M5: Total Ded. (₱) | N5: Taxable Comp. (₱) | O5: W/Tax (₱) | P5: 13th Mo. Prov. (₱) | Q5: OT/ Night Diff (₱) | R5: Reg. Hol. Days Worked | S5: Reg. Hol. Pay (₱) | T5: Spec. Hol. Days Worked | U5: Spec. Hol. Pay (₱) | V5: Net Pay (₱) | W5: SSS ER (₱) | X5: PH ER (₱) | Y5: HDMF ER (₱) | Z5: Total ER Cost (₱)
A6: 1 | B6: =Employee_Master!B4 -> EMP-001 | C6: =Employee_Master!C4 -> Juan dela Cruz | D6: =Employee_Master!H4 -> 30000 | E6: =IFERROR(IF(IFERROR(Employee_Master!P4,"")="Weekly",5,IF(IFERROR(Employee_Master!P4,"")="Monthly",22,11)),0) -> 11 | F6: =IFERROR(Employee_Master!I4*E6,0) -> 15000 | G6: =IFERROR(IF(D6=0,0,VLOOKUP(D6,SSS_Table!$B$4:$D$64,3,TRUE())*IF(IFERROR(Employee_Master!P4,"")<>"Semi-Monthly",1,IF(Payroll_Register!$K$3="Every Period",1,IF(Payroll_Register!$K$3="1st Half",IF(Payroll_Register!$C$3="1st Half",1,0),IF(Payroll_Register!$C$3="2nd Half",1,0))))/IF(IFERROR(Employee_Master!P4,"")="Weekly",4.33,IF(IFERROR(Employee_Master!P4,"")="Monthly",1,IF(Payroll_Register!$K$3="Every Period",2,1)))),0) -> 750 | H6: =IFERROR(IF(D6=0,0,MIN(MAX(D6*0.025,250),2500)*IF(IFERROR(Employee_Master!P4,"")<>"Semi-Monthly",1,IF(Payroll_Register!$K$3="Every Period",1,IF(Payroll_Register!$K$3="1st Half",IF(Payroll_Register!$C$3="1st Half",1,0),IF(Payroll_Register!$C$3="2nd Half",1,0))))/IF(IFERROR(Employee_Master!P4,"")="Weekly",4.33,IF(IFERROR(Employee_Master!P4,"")="Monthly",1,IF(Payroll_Register!$K$3="Every Period",2,1)))),0) -> 375 | I6: =IFERROR(IF(D6=0,0,MIN(D6*0.02,200)*IF(IFERROR(Employee_Master!P4,"")<>"Semi-Monthly",1,IF(Payroll_Register!$K$3="Every Period",1,IF(Payroll_Register!$K$3="1st Half",IF(Payroll_Register!$C$3="1st Half",1,0),IF(Payroll_Register!$C$3="2nd Half",1,0))))/IF(IFERROR(Employee_Master!P4,"")="Weekly",4.33,IF(IFERROR(Employee_Master!P4,"")="Monthly",1,IF(Payroll_Register!$K$3="Every Period",2,1)))),0) -> 100 | J6: =IFERROR(Attendance_Register!Q7,0) -> 0 | K6: 0 | L6: =IFERROR(F6+Q6+S6+U6,0) -> 15000 | M6: =IFERROR(G6+H6+I6+J6+K6+O6,0) -> 1728.7495 | N6: =IFERROR(L6-G6-H6-I6,0) -> 13775 | O6: =IFERROR(IF(D6=0,0,IF(N6<=0,0,IF(N6*IF(IFERROR(Employee_Master!P4,"")="Weekly",0.5,IF(IFERROR(Employee_Master!P4,"")="Monthly",2,1))<=10416.67,0,IF(N6*IF(IFERROR(Employee_Master!P4,"")="Weekly",0.5,IF(IFERROR(Employee_Master!P4,"")="Monthly",2,1))<=16666.67,(N6*IF(IFERROR(Employee_Master!P4,"")="Weekly",0.5,IF(IFERROR(Employee_Master!P4,"")="Monthly",2,1))-10416.67)*0.15,IF(N6*IF(IFERROR(Employee_Master!P4,"")="Weekly",0.5,IF(IFERROR(Employee_Master!P4,"")="Monthly",2,1))<=33333.33,937.5+(N6*IF(IFERROR(Employee_Master!P4,"")="Weekly",0.5,IF(IFERROR(Employee_Master!P4,"")="Monthly",2,1))-16666.67)*0.2,IF(N6*IF(IFERROR(Employee_Master!P4,"")="Weekly",0.5,IF(IFERROR(Employee_Master!P4,"")="Monthly",2,1))<=83333.33,4270.83+(N6*IF(IFERROR(Employee_Master!P4,"")="Weekly",0.5,IF(IFERROR(Employee_Master!P4,"")="Monthly",2,1))-33333.33)*0.25,IF(N6*IF(IFERROR(Employee_Master!P4,"")="Weekly",0.5,IF(IFERROR(Employee_Master!P4,"")="Monthly",2,1))<=333333.33,16770.83+(N6*IF(IFERROR(Employee_Master!P4,"")="Weekly",0.5,IF(IFERROR(Employee_Master!P4,"")="Monthly",2,1))-83333.33)*0.3,91770.83+(N6*IF(IFERROR(Employee_Master!P4,"")="Weekly",0.5,IF(IFERROR(Employee_Master!P4,"")="Monthly",2,1))-333333.33)*0.35))))))/IF(IFERROR(Employee_Master!P4,"")="Weekly",0.5,IF(IFERROR(Employee_Master!P4,"")="Monthly",2,1))),0) -> 503.7495 | P6: =IFERROR(IF(D6=0,0,D6/12/IF(IFERROR(Employee_Master!P4,"")="Weekly",4.33,IF(IFERROR(Employee_Master!P4,"")="Monthly",1,2))),0) -> 1250 | Q6: 0 | R6: 0 | S6: =IFERROR(Employee_Master!I4*R6*2,0) -> 0 | T6: 0 | U6: =IFERROR(Employee_Master!I4*T6*0.3,0) -> 0 | V6: =IFERROR(L6-M6,0) -> 13271.251 | W6: =IFERROR(IF(D6=0,0,VLOOKUP(D6,SSS_Table!$B$4:$E$64,4,TRUE())*IF(IFERROR(Employee_Master!P4,"")<>"Semi-Monthly",1,IF(Payroll_Register!$K$3="Every Period",1,IF(Payroll_Register!$K$3="1st Half",IF(Payroll_Register!$C$3="1st Half",1,0),IF(Payroll_Register!$C$3="2nd Half",1,0))))/IF(IFERROR(Employee_Master!P4,"")="Weekly",4.33,IF(IFERROR(Employee_Master!P4,"")="Monthly",1,IF(Payroll_Register!$K$3="Every Period",2,1)))),0) -> 1515 | X6: =IFERROR(H6,0) -> 375 | Y6: =IFERROR(I6,0) -> 100 | Z6: =IFERROR(W6+X6+Y6,0) -> 1990
A7: 2 | B7: =Employee_Master!B5 -> EMP-002 | C7: =Employee_Master!C5 -> Maria Santos | D7: =Employee_Master!H5 -> 25000 | E7: =IFERROR(IF(IFERROR(Employee_Master!P5,"")="Weekly",5,IF(IFERROR(Employee_Master!P5,"")="Monthly",22,11)),0) -> 11 | F7: =IFERROR(Employee_Master!I5*E7,0) -> 12500 | G7: =IFERROR(IF(D7=0,0,VLOOKUP(D7,SSS_Table!$B$4:$D$64,3,TRUE())*IF(IFERROR(Employee_Master!P5,"")<>"Semi-Monthly",1,IF(Payroll_Register!$K$3="Every Period",1,IF(Payroll_Register!$K$3="1st Half",IF(Payroll_Register!$C$3="1st Half",1,0),IF(Payroll_Register!$C$3="2nd Half",1,0))))/IF(IFERROR(Employee_Master!P5,"")="Weekly",4.33,IF(IFERROR(Employee_Master!P5,"")="Monthly",1,IF(Payroll_Register!$K$3="Every Period",2,1)))),0) -> 625 | H7: =IFERROR(IF(D7=0,0,MIN(MAX(D7*0.025,250),2500)*IF(IFERROR(Employee_Master!P5,"")<>"Semi-Monthly",1,IF(Payroll_Register!$K$3="Every Period",1,IF(Payroll_Register!$K$3="1st Half",IF(Payroll_Register!$C$3="1st Half",1,0),IF(Payroll_Register!$C$3="2nd Half",1,0))))/IF(IFERROR(Employee_Master!P5,"")="Weekly",4.33,IF(IFERROR(Employee_Master!P5,"")="Monthly",1,IF(Payroll_Register!$K$3="Every Period",2,1)))),0) -> 312.5 | I7: =IFERROR(IF(D7=0,0,MIN(D7*0.02,200)*IF(IFERROR(Employee_Master!P5,"")<>"Semi-Monthly",1,IF(Payroll_Register!$K$3="Every Period",1,IF(Payroll_Register!$K$3="1st Half",IF(Payroll_Register!$C$3="1st Half",1,0),IF(Payroll_Register!$C$3="2nd Half",1,0))))/IF(IFERROR(Employee_Master!P5,"")="Weekly",4.33,IF(IFERROR(Employee_Master!P5,"")="Monthly",1,IF(Payroll_Register!$K$3="Every Period",2,1)))),0) -> 100 | J7: =IFERROR(Attendance_Register!Q8,0) -> 0 | K7: 0 | L7: =IFERROR(F7+Q7+S7+U7,0) -> 12500 | M7: =IFERROR(G7+H7+I7+J7+K7+O7,0) -> 1194.3745 | N7: =IFERROR(L7-G7-H7-I7,0) -> 11462.5 | O7: =IFERROR(IF(D7=0,0,IF(N7<=0,0,IF(N7*IF(IFERROR(Employee_Master!P5,"")="Weekly",0.5,IF(IFERROR(Employee_Master!P5,"")="Monthly",2,1))<=10416.67,0,IF(N7*IF(IFERROR(Employee_Master!P5,"")="Weekly",0.5,IF(IFERROR(Employee_Master!P5,"")="Monthly",2,1))<=16666.67,(N7*IF(IFERROR(Employee_Master!P5,"")="Weekly",0.5,IF(IFERROR(Employee_Master!P5,"")="Monthly",2,1))-10416.67)*0.15,IF(N7*IF(IFERROR(Employee_Master!P5,"")="Weekly",0.5,IF(IFERROR(Employee_Master!P5,"")="Monthly",2,1))<=33333.33,937.5+(N7*IF(IFERROR(Employee_Master!P5,"")="Weekly",0.5,IF(IFERROR(Employee_Master!P5,"")="Monthly",2,1))-16666.67)*0.2,IF(N7*IF(IFERROR(Employee_Master!P5,"")="Weekly",0.5,IF(IFERROR(Employee_Master!P5,"")="Monthly",2,1))<=83333.33,4270.83+(N7*IF(IFERROR(Employee_Master!P5,"")="Weekly",0.5,IF(IFERROR(Employee_Master!P5,"")="Monthly",2,1))-33333.33)*0.25,IF(N7*IF(IFERROR(Employee_Master!P5,"")="Weekly",0.5,IF(IFERROR(Employee_Master!P5,"")="Monthly",2,1))<=333333.33,16770.83+(N7*IF(IFERROR(Employee_Master!P5,"")="Weekly",0.5,IF(IFERROR(Employee_Master!P5,"")="Monthly",2,1))-83333.33)*0.3,91770.83+(N7*IF(IFERROR(Employee_Master!P5,"")="Weekly",0.5,IF(IFERROR(Employee_Master!P5,"")="Monthly",2,1))-333333.33)*0.35))))))/IF(IFERROR(Employee_Master!P5,"")="Weekly",0.5,IF(IFERROR(Employee_Master!P5,"")="Monthly",2,1))),0) -> 156.8745 | P7: =IFERROR(IF(D7=0,0,D7/12/IF(IFERROR(Employee_Master!P5,"")="Weekly",4.33,IF(IFERROR(Employee_Master!P5,"")="Monthly",1,2))),0) -> 1041.6667 | Q7: 0 | R7: 0 | S7: =IFERROR(Employee_Master!I5*R7*2,0) -> 0 | T7: 0 | U7: =IFERROR(Employee_Master!I5*T7*0.3,0) -> 0 | V7: =IFERROR(L7-M7,0) -> 11305.625 | W7: =IFERROR(IF(D7=0,0,VLOOKUP(D7,SSS_Table!$B$4:$E$64,4,TRUE())*IF(IFERROR(Employee_Master!P5,"")<>"Semi-Monthly",1,IF(Payroll_Register!$K$3="Every Period",1,IF(Payroll_Register!$K$3="1st Half",IF(Payroll_Register!$C$3="1st Half",1,0),IF(Payroll_Register!$C$3="2nd Half",1,0))))/IF(IFERROR(Employee_Master!P5,"")="Weekly",4.33,IF(IFERROR(Employee_Master!P5,"")="Monthly",1,IF(Payroll_Register!$K$3="Every Period",2,1)))),0) -> 1265 | X7: =IFERROR(H7,0) -> 312.5 | Y7: =IFERROR(I7,0) -> 100 | Z7: =IFERROR(W7+X7+Y7,0) -> 1677.5
A8: 3 | B8: =Employee_Master!B6 -> EMP-003 | C8: =Employee_Master!C6 -> Pedro Reyes | D8: =Employee_Master!H6 -> 35000 | E8: =IFERROR(IF(IFERROR(Employee_Master!P6,"")="Weekly",5,IF(IFERROR(Employee_Master!P6,"")="Monthly",22,11)),0) -> 11 | F8: =IFERROR(Employee_Master!I6*E8,0) -> 17500 | G8: =IFERROR(IF(D8=0,0,VLOOKUP(D8,SSS_Table!$B$4:$D$64,3,TRUE())*IF(IFERROR(Employee_Master!P6,"")<>"Semi-Monthly",1,IF(Payroll_Register!$K$3="Every Period",1,IF(Payroll_Register!$K$3="1st Half",IF(Payroll_Register!$C$3="1st Half",1,0),IF(Payroll_Register!$C$3="2nd Half",1,0))))/IF(IFERROR(Employee_Master!P6,"")="Weekly",4.33,IF(IFERROR(Employee_Master!P6,"")="Monthly",1,IF(Payroll_Register!$K$3="Every Period",2,1)))),0) -> 875 | H8: =IFERROR(IF(D8=0,0,MIN(MAX(D8*0.025,250),2500)*IF(IFERROR(Employee_Master!P6,"")<>"Semi-Monthly",1,IF(Payroll_Register!$K$3="Every Period",1,IF(Payroll_Register!$K$3="1st Half",IF(Payroll_Register!$C$3="1st Half",1,0),IF(Payroll_Register!$C$3="2nd Half",1,0))))/IF(IFERROR(Employee_Master!P6,"")="Weekly",4.33,IF(IFERROR(Employee_Master!P6,"")="Monthly",1,IF(Payroll_Register!$K$3="Every Period",2,1)))),0) -> 437.5 | I8: =IFERROR(IF(D8=0,0,MIN(D8*0.02,200)*IF(IFERROR(Employee_Master!P6,"")<>"Semi-Monthly",1,IF(Payroll_Register!$K$3="Every Period",1,IF(Payroll_Register!$K$3="1st Half",IF(Payroll_Register!$C$3="1st Half",1,0),IF(Payroll_Register!$C$3="2nd Half",1,0))))/IF(IFERROR(Employee_Master!P6,"")="Weekly",4.33,IF(IFERROR(Employee_Master!P6,"")="Monthly",1,IF(Payroll_Register!$K$3="Every Period",2,1)))),0) -> 100 | J8: =IFERROR(Attendance_Register!Q9,0) -> 0 | K8: 0 | L8: =IFERROR(F8+Q8+S8+U8,0) -> 17500 | M8: =IFERROR(G8+H8+I8+J8+K8+O8,0) -> 2263.1245 | N8: =IFERROR(L8-G8-H8-I8,0) -> 16087.5 | O8: =IFERROR(IF(D8=0,0,IF(N8<=0,0,IF(N8*IF(IFERROR(Employee_Master!P6,"")="Weekly",0.5,IF(IFERROR(Employee_Master!P6,"")="Monthly",2,1))<=10416.67,0,IF(N8*IF(IFERROR(Employee_Master!P6,"")="Weekly",0.5,IF(IFERROR(Employee_Master!P6,"")="Monthly",2,1))<=16666.67,(N8*IF(IFERROR(Employee_Master!P6,"")="Weekly",0.5,IF(IFERROR(Employee_Master!P6,"")="Monthly",2,1))-10416.67)*0.15,IF(N8*IF(IFERROR(Employee_Master!P6,"")="Weekly",0.5,IF(IFERROR(Employee_Master!P6,"")="Monthly",2,1))<=33333.33,937.5+(N8*IF(IFERROR(Employee_Master!P6,"")="Weekly",0.5,IF(IFERROR(Employee_Master!P6,"")="Monthly",2,1))-16666.67)*0.2,IF(N8*IF(IFERROR(Employee_Master!P6,"")="Weekly",0.5,IF(IFERROR(Employee_Master!P6,"")="Monthly",2,1))<=83333.33,4270.83+(N8*IF(IFERROR(Employee_Master!P6,"")="Weekly",0.5,IF(IFERROR(Employee_Master!P6,"")="Monthly",2,1))-33333.33)*0.25,IF(N8*IF(IFERROR(Employee_Master!P6,"")="Weekly",0.5,IF(IFERROR(Employee_Master!P6,"")="Monthly",2,1))<=333333.33,16770.83+(N8*IF(IFERROR(Employee_Master!P6,"")="Weekly",0.5,IF(IFERROR(Employee_Master!P6,"")="Monthly",2,1))-83333.33)*0.3,91770.83+(N8*IF(IFERROR(Employee_Master!P6,"")="Weekly",0.5,IF(IFERROR(Employee_Master!P6,"")="Monthly",2,1))-333333.33)*0.35))))))/IF(IFERROR(Employee_Master!P6,"")="Weekly",0.5,IF(IFERROR(Employee_Master!P6,"")="Monthly",2,1))),0) -> 850.6245 | P8: =IFERROR(IF(D8=0,0,D8/12/IF(IFERROR(Employee_Master!P6,"")="Weekly",4.33,IF(IFERROR(Employee_Master!P6,"")="Monthly",1,2))),0) -> 1458.3333 | Q8: 0 | R8: 0 | S8: =IFERROR(Employee_Master!I6*R8*2,0) -> 0 | T8: 0 | U8: =IFERROR(Employee_Master!I6*T8*0.3,0) -> 0 | V8: =IFERROR(L8-M8,0) -> 15236.876 | W8: =IFERROR(IF(D8=0,0,VLOOKUP(D8,SSS_Table!$B$4:$E$64,4,TRUE())*IF(IFERROR(Employee_Master!P6,"")<>"Semi-Monthly",1,IF(Payroll_Register!$K$3="Every Period",1,IF(Payroll_Register!$K$3="1st Half",IF(Payroll_Register!$C$3="1st Half",1,0),IF(Payroll_Register!$C$3="2nd Half",1,0))))/IF(IFERROR(Employee_Master!P6,"")="Weekly",4.33,IF(IFERROR(Employee_Master!P6,"")="Monthly",1,IF(Payroll_Register!$K$3="Every Period",2,1)))),0) -> 1765 | X8: =IFERROR(H8,0) -> 437.5 | Y8: =IFERROR(I8,0) -> 100 | Z8: =IFERROR(W8+X8+Y8,0) -> 2302.5
A9: 4 | B9: =Employee_Master!B7 -> EMP-004 | C9: =Employee_Master!C7 -> Ana Gonzales | D9: =Employee_Master!H7 -> 18000 | E9: =IFERROR(IF(IFERROR(Employee_Master!P7,"")="Weekly",5,IF(IFERROR(Employee_Master!P7,"")="Monthly",22,11)),0) -> 11 | F9: =IFERROR(Employee_Master!I7*E9,0) -> 9000 | G9: =IFERROR(IF(D9=0,0,VLOOKUP(D9,SSS_Table!$B$4:$D$64,3,TRUE())*IF(IFERROR(Employee_Master!P7,"")<>"Semi-Monthly",1,IF(Payroll_Register!$K$3="Every Period",1,IF(Payroll_Register!$K$3="1st Half",IF(Payroll_Register!$C$3="1st Half",1,0),IF(Payroll_Register!$C$3="2nd Half",1,0))))/IF(IFERROR(Employee_Master!P7,"")="Weekly",4.33,IF(IFERROR(Employee_Master!P7,"")="Monthly",1,IF(Payroll_Register!$K$3="Every Period",2,1)))),0) -> 450 | H9: =IFERROR(IF(D9=0,0,MIN(MAX(D9*0.025,250),2500)*IF(IFERROR(Employee_Master!P7,"")<>"Semi-Monthly",1,IF(Payroll_Register!$K$3="Every Period",1,IF(Payroll_Register!$K$3="1st Half",IF(Payroll_Register!$C$3="1st Half",1,0),IF(Payroll_Register!$C$3="2nd Half",1,0))))/IF(IFERROR(Employee_Master!P7,"")="Weekly",4.33,IF(IFERROR(Employee_Master!P7,"")="Monthly",1,IF(Payroll_Register!$K$3="Every Period",2,1)))),0) -> 225 | I9: =IFERROR(IF(D9=0,0,MIN(D9*0.02,200)*IF(IFERROR(Employee_Master!P7,"")<>"Semi-Monthly",1,IF(Payroll_Register!$K$3="Every Period",1,IF(Payroll_Register!$K$3="1st Half",IF(Payroll_Register!$C$3="1st Half",1,0),IF(Payroll_Register!$C$3="2nd Half",1,0))))/IF(IFERROR(Employee_Master!P7,"")="Weekly",4.33,IF(IFERROR(Employee_Master!P7,"")="Monthly",1,IF(Payroll_Register!$K$3="Every Period",2,1)))),0) -> 100 | J9: =IFERROR(Attendance_Register!Q10,0) -> 0 | K9: 0 | L9: =IFERROR(F9+Q9+S9+U9,0) -> 9000 | M9: =IFERROR(G9+H9+I9+J9+K9+O9,0) -> 775 | N9: =IFERROR(L9-G9-H9-I9,0) -> 8225 | O9: =IFERROR(IF(D9=0,0,IF(N9<=0,0,IF(N9*IF(IFERROR(Employee_Master!P7,"")="Weekly",0.5,IF(IFERROR(Employee_Master!P7,"")="Monthly",2,1))<=10416.67,0,IF(N9*IF(IFERROR(Employee_Master!P7,"")="Weekly",0.5,IF(IFERROR(Employee_Master!P7,"")="Monthly",2,1))<=16666.67,(N9*IF(IFERROR(Employee_Master!P7,"")="Weekly",0.5,IF(IFERROR(Employee_Master!P7,"")="Monthly",2,1))-10416.67)*0.15,IF(N9*IF(IFERROR(Employee_Master!P7,"")="Weekly",0.5,IF(IFERROR(Employee_Master!P7,"")="Monthly",2,1))<=33333.33,937.5+(N9*IF(IFERROR(Employee_Master!P7,"")="Weekly",0.5,IF(IFERROR(Employee_Master!P7,"")="Monthly",2,1))-16666.67)*0.2,IF(N9*IF(IFERROR(Employee_Master!P7,"")="Weekly",0.5,IF(IFERROR(Employee_Master!P7,"")="Monthly",2,1))<=83333.33,4270.83+(N9*IF(IFERROR(Employee_Master!P7,"")="Weekly",0.5,IF(IFERROR(Employee_Master!P7,"")="Monthly",2,1))-33333.33)*0.25,IF(N9*IF(IFERROR(Employee_Master!P7,"")="Weekly",0.5,IF(IFERROR(Employee_Master!P7,"")="Monthly",2,1))<=333333.33,16770.83+(N9*IF(IFERROR(Employee_Master!P7,"")="Weekly",0.5,IF(IFERROR(Employee_Master!P7,"")="Monthly",2,1))-83333.33)*0.3,91770.83+(N9*IF(IFERROR(Employee_Master!P7,"")="Weekly",0.5,IF(IFERROR(Employee_Master!P7,"")="Monthly",2,1))-333333.33)*0.35))))))/IF(IFERROR(Employee_Master!P7,"")="Weekly",0.5,IF(IFERROR(Employee_Master!P7,"")="Monthly",2,1))),0) -> 0 | P9: =IFERROR(IF(D9=0,0,D9/12/IF(IFERROR(Employee_Master!P7,"")="Weekly",4.33,IF(IFERROR(Employee_Master!P7,"")="Monthly",1,2))),0) -> 750 | Q9: 0 | R9: 0 | S9: =IFERROR(Employee_Master!I7*R9*2,0) -> 0 | T9: 0 | U9: =IFERROR(Employee_Master!I7*T9*0.3,0) -> 0 | V9: =IFERROR(L9-M9,0) -> 8225 | W9: =IFERROR(IF(D9=0,0,VLOOKUP(D9,SSS_Table!$B$4:$E$64,4,TRUE())*IF(IFERROR(Employee_Master!P7,"")<>"Semi-Monthly",1,IF(Payroll_Register!$K$3="Every Period",1,IF(Payroll_Register!$K$3="1st Half",IF(Payroll_Register!$C$3="1st Half",1,0),IF(Payroll_Register!$C$3="2nd Half",1,0))))/IF(IFERROR(Employee_Master!P7,"")="Weekly",4.33,IF(IFERROR(Employee_Master!P7,"")="Monthly",1,IF(Payroll_Register!$K$3="Every Period",2,1)))),0) -> 915 | X9: =IFERROR(H9,0) -> 225 | Y9: =IFERROR(I9,0) -> 100 | Z9: =IFERROR(W9+X9+Y9,0) -> 1240
A10: 5 | B10: =Employee_Master!B8 -> EMP-005 | C10: =Employee_Master!C8 -> Jose Bautista | D10: =Employee_Master!H8 -> 16000 | E10: =IFERROR(IF(IFERROR(Employee_Master!P8,"")="Weekly",5,IF(IFERROR(Employee_Master!P8,"")="Monthly",22,11)),0) -> 11 | F10: =IFERROR(Employee_Master!I8*E10,0) -> 8000 | G10: =IFERROR(IF(D10=0,0,VLOOKUP(D10,SSS_Table!$B$4:$D$64,3,TRUE())*IF(IFERROR(Employee_Master!P8,"")<>"Semi-Monthly",1,IF(Payroll_Register!$K$3="Every Period",1,IF(Payroll_Register!$K$3="1st Half",IF(Payroll_Register!$C$3="1st Half",1,0),IF(Payroll_Register!$C$3="2nd Half",1,0))))/IF(IFERROR(Employee_Master!P8,"")="Weekly",4.33,IF(IFERROR(Employee_Master!P8,"")="Monthly",1,IF(Payroll_Register!$K$3="Every Period",2,1)))),0) -> 400 | H10: =IFERROR(IF(D10=0,0,MIN(MAX(D10*0.025,250),2500)*IF(IFERROR(Employee_Master!P8,"")<>"Semi-Monthly",1,IF(Payroll_Register!$K$3="Every Period",1,IF(Payroll_Register!$K$3="1st Half",IF(Payroll_Register!$C$3="1st Half",1,0),IF(Payroll_Register!$C$3="2nd Half",1,0))))/IF(IFERROR(Employee_Master!P8,"")="Weekly",4.33,IF(IFERROR(Employee_Master!P8,"")="Monthly",1,IF(Payroll_Register!$K$3="Every Period",2,1)))),0) -> 200 | I10: =IFERROR(IF(D10=0,0,MIN(D10*0.02,200)*IF(IFERROR(Employee_Master!P8,"")<>"Semi-Monthly",1,IF(Payroll_Register!$K$3="Every Period",1,IF(Payroll_Register!$K$3="1st Half",IF(Payroll_Register!$C$3="1st Half",1,0),IF(Payroll_Register!$C$3="2nd Half",1,0))))/IF(IFERROR(Employee_Master!P8,"")="Weekly",4.33,IF(IFERROR(Employee_Master!P8,"")="Monthly",1,IF(Payroll_Register!$K$3="Every Period",2,1)))),0) -> 100 | J10: =IFERROR(Attendance_Register!Q11,0) -> 0 | K10: 0 | L10: =IFERROR(F10+Q10+S10+U10,0) -> 8000 | M10: =IFERROR(G10+H10+I10+J10+K10+O10,0) -> 700 | N10: =IFERROR(L10-G10-H10-I10,0) -> 7300 | O10: =IFERROR(IF(D10=0,0,IF(N10<=0,0,IF(N10*IF(IFERROR(Employee_Master!P8,"")="Weekly",0.5,IF(IFERROR(Employee_Master!P8,"")="Monthly",2,1))<=10416.67,0,IF(N10*IF(IFERROR(Employee_Master!P8,"")="Weekly",0.5,IF(IFERROR(Employee_Master!P8,"")="Monthly",2,1))<=16666.67,(N10*IF(IFERROR(Employee_Master!P8,"")="Weekly",0.5,IF(IFERROR(Employee_Master!P8,"")="Monthly",2,1))-10416.67)*0.15,IF(N10*IF(IFERROR(Employee_Master!P8,"")="Weekly",0.5,IF(IFERROR(Employee_Master!P8,"")="Monthly",2,1))<=33333.33,937.5+(N10*IF(IFERROR(Employee_Master!P8,"")="Weekly",0.5,IF(IFERROR(Employee_Master!P8,"")="Monthly",2,1))-16666.67)*0.2,IF(N10*IF(IFERROR(Employee_Master!P8,"")="Weekly",0.5,IF(IFERROR(Employee_Master!P8,"")="Monthly",2,1))<=83333.33,4270.83+(N10*IF(IFERROR(Employee_Master!P8,"")="Weekly",0.5,IF(IFERROR(Employee_Master!P8,"")="Monthly",2,1))-33333.33)*0.25,IF(N10*IF(IFERROR(Employee_Master!P8,"")="Weekly",0.5,IF(IFERROR(Employee_Master!P8,"")="Monthly",2,1))<=333333.33,16770.83+(N10*IF(IFERROR(Employee_Master!P8,"")="Weekly",0.5,IF(IFERROR(Employee_Master!P8,"")="Monthly",2,1))-83333.33)*0.3,91770.83+(N10*IF(IFERROR(Employee_Master!P8,"")="Weekly",0.5,IF(IFERROR(Employee_Master!P8,"")="Monthly",2,1))-333333.33)*0.35))))))/IF(IFERROR(Employee_Master!P8,"")="Weekly",0.5,IF(IFERROR(Employee_Master!P8,"")="Monthly",2,1))),0) -> 0 | P10: =IFERROR(IF(D10=0,0,D10/12/IF(IFERROR(Employee_Master!P8,"")="Weekly",4.33,IF(IFERROR(Employee_Master!P8,"")="Monthly",1,2))),0) -> 666.66667 | Q10: 0 | R10: 0 | S10: =IFERROR(Employee_Master!I8*R10*2,0) -> 0 | T10: 0 | U10: =IFERROR(Employee_Master!I8*T10*0.3,0) -> 0 | V10: =IFERROR(L10-M10,0) -> 7300 | W10: =IFERROR(IF(D10=0,0,VLOOKUP(D10,SSS_Table!$B$4:$E$64,4,TRUE())*IF(IFERROR(Employee_Master!P8,"")<>"Semi-Monthly",1,IF(Payroll_Register!$K$3="Every Period",1,IF(Payroll_Register!$K$3="1st Half",IF(Payroll_Register!$C$3="1st Half",1,0),IF(Payroll_Register!$C$3="2nd Half",1,0))))/IF(IFERROR(Employee_Master!P8,"")="Weekly",4.33,IF(IFERROR(Employee_Master!P8,"")="Monthly",1,IF(Payroll_Register!$K$3="Every Period",2,1)))),0) -> 815 | X10: =IFERROR(H10,0) -> 200 | Y10: =IFERROR(I10,0) -> 100 | Z10: =IFERROR(W10+X10+Y10,0) -> 1115
A11: 6 | B11: =Employee_Master!B9 -> EMP-006 | C11: =Employee_Master!C9 -> 0 | D11: =Employee_Master!H9 -> 0 | E11: =IFERROR(IF(IFERROR(Employee_Master!P9,"")="Weekly",5,IF(IFERROR(Employee_Master!P9,"")="Monthly",22,11)),0) -> 11 | F11: =IFERROR(Employee_Master!I9*E11,0) -> 0 | G11: =IFERROR(IF(D11=0,0,VLOOKUP(D11,SSS_Table!$B$4:$D$64,3,TRUE())*IF(IFERROR(Employee_Master!P9,"")<>"Semi-Monthly",1,IF(Payroll_Register!$K$3="Every Period",1,IF(Payroll_Register!$K$3="1st Half",IF(Payroll_Register!$C$3="1st Half",1,0),IF(Payroll_Register!$C$3="2nd Half",1,0))))/IF(IFERROR(Employee_Master!P9,"")="Weekly",4.33,IF(IFERROR(Employee_Master!P9,"")="Monthly",1,IF(Payroll_Register!$K$3="Every Period",2,1)))),0) -> 0 | H11: =IFERROR(IF(D11=0,0,MIN(MAX(D11*0.025,250),2500)*IF(IFERROR(Employee_Master!P9,"")<>"Semi-Monthly",1,IF(Payroll_Register!$K$3="Every Period",1,IF(Payroll_Register!$K$3="1st Half",IF(Payroll_Register!$C$3="1st Half",1,0),IF(Payroll_Register!$C$3="2nd Half",1,0))))/IF(IFERROR(Employee_Master!P9,"")="Weekly",4.33,IF(IFERROR(Employee_Master!P9,"")="Monthly",1,IF(Payroll_Register!$K$3="Every Period",2,1)))),0) -> 0 | I11: =IFERROR(IF(D11=0,0,MIN(D11*0.02,200)*IF(IFERROR(Employee_Master!P9,"")<>"Semi-Monthly",1,IF(Payroll_Register!$K$3="Every Period",1,IF(Payroll_Register!$K$3="1st Half",IF(Payroll_Register!$C$3="1st Half",1,0),IF(Payroll_Register!$C$3="2nd Half",1,0))))/IF(IFERROR(Employee_Master!P9,"")="Weekly",4.33,IF(IFERROR(Employee_Master!P9,"")="Monthly",1,IF(Payroll_Register!$K$3="Every Period",2,1)))),0) -> 0 | J11: =IFERROR(Attendance_Register!Q12,0) -> 0 | K11: 0 | L11: =IFERROR(F11+Q11+S11+U11,0) -> 0 | M11: =IFERROR(G11+H11+I11+J11+K11+O11,0) -> 0 | N11: =IFERROR(L11-G11-H11-I11,0) -> 0 | O11: =IFERROR(IF(D11=0,0,IF(N11<=0,0,IF(N11*IF(IFERROR(Employee_Master!P9,"")="Weekly",0.5,IF(IFERROR(Employee_Master!P9,"")="Monthly",2,1))<=10416.67,0,IF(N11*IF(IFERROR(Employee_Master!P9,"")="Weekly",0.5,IF(IFERROR(Employee_Master!P9,"")="Monthly",2,1))<=16666.67,(N11*IF(IFERROR(Employee_Master!P9,"")="Weekly",0.5,IF(IFERROR(Employee_Master!P9,"")="Monthly",2,1))-10416.67)*0.15,IF(N11*IF(IFERROR(Employee_Master!P9,"")="Weekly",0.5,IF(IFERROR(Employee_Master!P9,"")="Monthly",2,1))<=33333.33,937.5+(N11*IF(IFERROR(Employee_Master!P9,"")="Weekly",0.5,IF(IFERROR(Employee_Master!P9,"")="Monthly",2,1))-16666.67)*0.2,IF(N11*IF(IFERROR(Employee_Master!P9,"")="Weekly",0.5,IF(IFERROR(Employee_Master!P9,"")="Monthly",2,1))<=83333.33,4270.83+(N11*IF(IFERROR(Employee_Master!P9,"")="Weekly",0.5,IF(IFERROR(Employee_Master!P9,"")="Monthly",2,1))-33333.33)*0.25,IF(N11*IF(IFERROR(Employee_Master!P9,"")="Weekly",0.5,IF(IFERROR(Employee_Master!P9,"")="Monthly",2,1))<=333333.33,16770.83+(N11*IF(IFERROR(Employee_Master!P9,"")="Weekly",0.5,IF(IFERROR(Employee_Master!P9,"")="Monthly",2,1))-83333.33)*0.3,91770.83+(N11*IF(IFERROR(Employee_Master!P9,"")="Weekly",0.5,IF(IFERROR(Employee_Master!P9,"")="Monthly",2,1))-333333.33)*0.35))))))/IF(IFERROR(Employee_Master!P9,"")="Weekly",0.5,IF(IFERROR(Employee_Master!P9,"")="Monthly",2,1))),0) -> 0 | P11: =IFERROR(IF(D11=0,0,D11/12/IF(IFERROR(Employee_Master!P9,"")="Weekly",4.33,IF(IFERROR(Employee_Master!P9,"")="Monthly",1,2))),0) -> 0 | Q11: 0 | R11: 0 | S11: =IFERROR(Employee_Master!I9*R11*2,0) -> 0 | T11: 0 | U11: =IFERROR(Employee_Master!I9*T11*0.3,0) -> 0 | V11: =IFERROR(L11-M11,0) -> 0 | W11: =IFERROR(IF(D11=0,0,VLOOKUP(D11,SSS_Table!$B$4:$E$64,4,TRUE())*IF(IFERROR(Employee_Master!P9,"")<>"Semi-Monthly",1,IF(Payroll_Register!$K$3="Every Period",1,IF(Payroll_Register!$K$3="1st Half",IF(Payroll_Register!$C$3="1st Half",1,0),IF(Payroll_Register!$C$3="2nd Half",1,0))))/IF(IFERROR(Employee_Master!P9,"")="Weekly",4.33,IF(IFERROR(Employee_Master!P9,"")="Monthly",1,IF(Payroll_Register!$K$3="Every Period",2,1)))),0) -> 0 | X11: =IFERROR(H11,0) -> 0 | Y11: =IFERROR(I11,0) -> 0 | Z11: =IFERROR(W11+X11+Y11,0) -> 0
A12: 7 | B12: =Employee_Master!B10 -> EMP-007 | C12: =Employee_Master!C10 -> 0 | D12: =Employee_Master!H10 -> 0 | E12: =IFERROR(IF(IFERROR(Employee_Master!P10,"")="Weekly",5,IF(IFERROR(Employee_Master!P10,"")="Monthly",22,11)),0) -> 11 | F12: =IFERROR(Employee_Master!I10*E12,0) -> 0 | G12: =IFERROR(IF(D12=0,0,VLOOKUP(D12,SSS_Table!$B$4:$D$64,3,TRUE())*IF(IFERROR(Employee_Master!P10,"")<>"Semi-Monthly",1,IF(Payroll_Register!$K$3="Every Period",1,IF(Payroll_Register!$K$3="1st Half",IF(Payroll_Register!$C$3="1st Half",1,0),IF(Payroll_Register!$C$3="2nd Half",1,0))))/IF(IFERROR(Employee_Master!P10,"")="Weekly",4.33,IF(IFERROR(Employee_Master!P10,"")="Monthly",1,IF(Payroll_Register!$K$3="Every Period",2,1)))),0) -> 0 | H12: =IFERROR(IF(D12=0,0,MIN(MAX(D12*0.025,250),2500)*IF(IFERROR(Employee_Master!P10,"")<>"Semi-Monthly",1,IF(Payroll_Register!$K$3="Every Period",1,IF(Payroll_Register!$K$3="1st Half",IF(Payroll_Register!$C$3="1st Half",1,0),IF(Payroll_Register!$C$3="2nd Half",1,0))))/IF(IFERROR(Employee_Master!P10,"")="Weekly",4.33,IF(IFERROR(Employee_Master!P10,"")="Monthly",1,IF(Payroll_Register!$K$3="Every Period",2,1)))),0) -> 0 | I12: =IFERROR(IF(D12=0,0,MIN(D12*0.02,200)*IF(IFERROR(Employee_Master!P10,"")<>"Semi-Monthly",1,IF(Payroll_Register!$K$3="Every Period",1,IF(Payroll_Register!$K$3="1st Half",IF(Payroll_Register!$C$3="1st Half",1,0),IF(Payroll_Register!$C$3="2nd Half",1,0))))/IF(IFERROR(Employee_Master!P10,"")="Weekly",4.33,IF(IFERROR(Employee_Master!P10,"")="Monthly",1,IF(Payroll_Register!$K$3="Every Period",2,1)))),0) -> 0 | J12: =IFERROR(Attendance_Register!Q13,0) -> 0 | K12: 0 | L12: =IFERROR(F12+Q12+S12+U12,0) -> 0 | M12: =IFERROR(G12+H12+I12+J12+K12+O12,0) -> 0 | N12: =IFERROR(L12-G12-H12-I12,0) -> 0 | O12: =IFERROR(IF(D12=0,0,IF(N12<=0,0,IF(N12*IF(IFERROR(Employee_Master!P10,"")="Weekly",0.5,IF(IFERROR(Employee_Master!P10,"")="Monthly",2,1))<=10416.67,0,IF(N12*IF(IFERROR(Employee_Master!P10,"")="Weekly",0.5,IF(IFERROR(Employee_Master!P10,"")="Monthly",2,1))<=16666.67,(N12*IF(IFERROR(Employee_Master!P10,"")="Weekly",0.5,IF(IFERROR(Employee_Master!P10,"")="Monthly",2,1))-10416.67)*0.15,IF(N12*IF(IFERROR(Employee_Master!P10,"")="Weekly",0.5,IF(IFERROR(Employee_Master!P10,"")="Monthly",2,1))<=33333.33,937.5+(N12*IF(IFERROR(Employee_Master!P10,"")="Weekly",0.5,IF(IFERROR(Employee_Master!P10,"")="Monthly",2,1))-16666.67)*0.2,IF(N12*IF(IFERROR(Employee_Master!P10,"")="Weekly",0.5,IF(IFERROR(Employee_Master!P10,"")="Monthly",2,1))<=83333.33,4270.83+(N12*IF(IFERROR(Employee_Master!P10,"")="Weekly",0.5,IF(IFERROR(Employee_Master!P10,"")="Monthly",2,1))-33333.33)*0.25,IF(N12*IF(IFERROR(Employee_Master!P10,"")="Weekly",0.5,IF(IFERROR(Employee_Master!P10,"")="Monthly",2,1))<=333333.33,16770.83+(N12*IF(IFERROR(Employee_Master!P10,"")="Weekly",0.5,IF(IFERROR(Employee_Master!P10,"")="Monthly",2,1))-83333.33)*0.3,91770.83+(N12*IF(IFERROR(Employee_Master!P10,"")="Weekly",0.5,IF(IFERROR(Employee_Master!P10,"")="Monthly",2,1))-333333.33)*0.35))))))/IF(IFERROR(Employee_Master!P10,"")="Weekly",0.5,IF(IFERROR(Employee_Master!P10,"")="Monthly",2,1))),0) -> 0 | P12: =IFERROR(IF(D12=0,0,D12/12/IF(IFERROR(Employee_Master!P10,"")="Weekly",4.33,IF(IFERROR(Employee_Master!P10,"")="Monthly",1,2))),0) -> 0 | Q12: 0 | R12: 0 | S12: =IFERROR(Employee_Master!I10*R12*2,0) -> 0 | T12: 0 | U12: =IFERROR(Employee_Master!I10*T12*0.3,0) -> 0 | V12: =IFERROR(L12-M12,0) -> 0 | W12: =IFERROR(IF(D12=0,0,VLOOKUP(D12,SSS_Table!$B$4:$E$64,4,TRUE())*IF(IFERROR(Employee_Master!P10,"")<>"Semi-Monthly",1,IF(Payroll_Register!$K$3="Every Period",1,IF(Payroll_Register!$K$3="1st Half",IF(Payroll_Register!$C$3="1st Half",1,0),IF(Payroll_Register!$C$3="2nd Half",1,0))))/IF(IFERROR(Employee_Master!P10,"")="Weekly",4.33,IF(IFERROR(Employee_Master!P10,"")="Monthly",1,IF(Payroll_Register!$K$3="Every Period",2,1)))),0) -> 0 | X12: =IFERROR(H12,0) -> 0 | Y12: =IFERROR(I12,0) -> 0 | Z12: =IFERROR(W12+X12+Y12,0) -> 0
A13: 8 | B13: =Employee_Master!B11 -> EMP-008 | C13: =Employee_Master!C11 -> 0 | D13: =Employee_Master!H11 -> 0 | E13: =IFERROR(IF(IFERROR(Employee_Master!P11,"")="Weekly",5,IF(IFERROR(Employee_Master!P11,"")="Monthly",22,11)),0) -> 11 | F13: =IFERROR(Employee_Master!I11*E13,0) -> 0 | G13: =IFERROR(IF(D13=0,0,VLOOKUP(D13,SSS_Table!$B$4:$D$64,3,TRUE())*IF(IFERROR(Employee_Master!P11,"")<>"Semi-Monthly",1,IF(Payroll_Register!$K$3="Every Period",1,IF(Payroll_Register!$K$3="1st Half",IF(Payroll_Register!$C$3="1st Half",1,0),IF(Payroll_Register!$C$3="2nd Half",1,0))))/IF(IFERROR(Employee_Master!P11,"")="Weekly",4.33,IF(IFERROR(Employee_Master!P11,"")="Monthly",1,IF(Payroll_Register!$K$3="Every Period",2,1)))),0) -> 0 | H13: =IFERROR(IF(D13=0,0,MIN(MAX(D13*0.025,250),2500)*IF(IFERROR(Employee_Master!P11,"")<>"Semi-Monthly",1,IF(Payroll_Register!$K$3="Every Period",1,IF(Payroll_Register!$K$3="1st Half",IF(Payroll_Register!$C$3="1st Half",1,0),IF(Payroll_Register!$C$3="2nd Half",1,0))))/IF(IFERROR(Employee_Master!P11,"")="Weekly",4.33,IF(IFERROR(Employee_Master!P11,"")="Monthly",1,IF(Payroll_Register!$K$3="Every Period",2,1)))),0) -> 0 | I13: =IFERROR(IF(D13=0,0,MIN(D13*0.02,200)*IF(IFERROR(Employee_Master!P11,"")<>"Semi-Monthly",1,IF(Payroll_Register!$K$3="Every Period",1,IF(Payroll_Register!$K$3="1st Half",IF(Payroll_Register!$C$3="1st Half",1,0),IF(Payroll_Register!$C$3="2nd Half",1,0))))/IF(IFERROR(Employee_Master!P11,"")="Weekly",4.33,IF(IFERROR(Employee_Master!P11,"")="Monthly",1,IF(Payroll_Register!$K$3="Every Period",2,1)))),0) -> 0 | J13: =IFERROR(Attendance_Register!Q14,0) -> 0 | K13: 0 | L13: =IFERROR(F13+Q13+S13+U13,0) -> 0 | M13: =IFERROR(G13+H13+I13+J13+K13+O13,0) -> 0 | N13: =IFERROR(L13-G13-H13-I13,0) -> 0 | O13: =IFERROR(IF(D13=0,0,IF(N13<=0,0,IF(N13*IF(IFERROR(Employee_Master!P11,"")="Weekly",0.5,IF(IFERROR(Employee_Master!P11,"")="Monthly",2,1))<=10416.67,0,IF(N13*IF(IFERROR(Employee_Master!P11,"")="Weekly",0.5,IF(IFERROR(Employee_Master!P11,"")="Monthly",2,1))<=16666.67,(N13*IF(IFERROR(Employee_Master!P11,"")="Weekly",0.5,IF(IFERROR(Employee_Master!P11,"")="Monthly",2,1))-10416.67)*0.15,IF(N13*IF(IFERROR(Employee_Master!P11,"")="Weekly",0.5,IF(IFERROR(Employee_Master!P11,"")="Monthly",2,1))<=33333.33,937.5+(N13*IF(IFERROR(Employee_Master!P11,"")="Weekly",0.5,IF(IFERROR(Employee_Master!P11,"")="Monthly",2,1))-16666.67)*0.2,IF(N13*IF(IFERROR(Employee_Master!P11,"")="Weekly",0.5,IF(IFERROR(Employee_Master!P11,"")="Monthly",2,1))<=83333.33,4270.83+(N13*IF(IFERROR(Employee_Master!P11,"")="Weekly",0.5,IF(IFERROR(Employee_Master!P11,"")="Monthly",2,1))-33333.33)*0.25,IF(N13*IF(IFERROR(Employee_Master!P11,"")="Weekly",0.5,IF(IFERROR(Employee_Master!P11,"")="Monthly",2,1))<=333333.33,16770.83+(N13*IF(IFERROR(Employee_Master!P11,"")="Weekly",0.5,IF(IFERROR(Employee_Master!P11,"")="Monthly",2,1))-83333.33)*0.3,91770.83+(N13*IF(IFERROR(Employee_Master!P11,"")="Weekly",0.5,IF(IFERROR(Employee_Master!P11,"")="Monthly",2,1))-333333.33)*0.35))))))/IF(IFERROR(Employee_Master!P11,"")="Weekly",0.5,IF(IFERROR(Employee_Master!P11,"")="Monthly",2,1))),0) -> 0 | P13: =IFERROR(IF(D13=0,0,D13/12/IF(IFERROR(Employee_Master!P11,"")="Weekly",4.33,IF(IFERROR(Employee_Master!P11,"")="Monthly",1,2))),0) -> 0 | Q13: 0 | R13: 0 | S13: =IFERROR(Employee_Master!I11*R13*2,0) -> 0 | T13: 0 | U13: =IFERROR(Employee_Master!I11*T13*0.3,0) -> 0 | V13: =IFERROR(L13-M13,0) -> 0 | W13: =IFERROR(IF(D13=0,0,VLOOKUP(D13,SSS_Table!$B$4:$E$64,4,TRUE())*IF(IFERROR(Employee_Master!P11,"")<>"Semi-Monthly",1,IF(Payroll_Register!$K$3="Every Period",1,IF(Payroll_Register!$K$3="1st Half",IF(Payroll_Register!$C$3="1st Half",1,0),IF(Payroll_Register!$C$3="2nd Half",1,0))))/IF(IFERROR(Employee_Master!P11,"")="Weekly",4.33,IF(IFERROR(Employee_Master!P11,"")="Monthly",1,IF(Payroll_Register!$K$3="Every Period",2,1)))),0) -> 0 | X13: =IFERROR(H13,0) -> 0 | Y13: =IFERROR(I13,0) -> 0 | Z13: =IFERROR(W13+X13+Y13,0) -> 0
A14: 9 | B14: =Employee_Master!B12 -> EMP-009 | C14: =Employee_Master!C12 -> 0 | D14: =Employee_Master!H12 -> 0 | E14: =IFERROR(IF(IFERROR(Employee_Master!P12,"")="Weekly",5,IF(IFERROR(Employee_Master!P12,"")="Monthly",22,11)),0) -> 11 | F14: =IFERROR(Employee_Master!I12*E14,0) -> 0 | G14: =IFERROR(IF(D14=0,0,VLOOKUP(D14,SSS_Table!$B$4:$D$64,3,TRUE())*IF(IFERROR(Employee_Master!P12,"")<>"Semi-Monthly",1,IF(Payroll_Register!$K$3="Every Period",1,IF(Payroll_Register!$K$3="1st Half",IF(Payroll_Register!$C$3="1st Half",1,0),IF(Payroll_Register!$C$3="2nd Half",1,0))))/IF(IFERROR(Employee_Master!P12,"")="Weekly",4.33,IF(IFERROR(Employee_Master!P12,"")="Monthly",1,IF(Payroll_Register!$K$3="Every Period",2,1)))),0) -> 0 | H14: =IFERROR(IF(D14=0,0,MIN(MAX(D14*0.025,250),2500)*IF(IFERROR(Employee_Master!P12,"")<>"Semi-Monthly",1,IF(Payroll_Register!$K$3="Every Period",1,IF(Payroll_Register!$K$3="1st Half",IF(Payroll_Register!$C$3="1st Half",1,0),IF(Payroll_Register!$C$3="2nd Half",1,0))))/IF(IFERROR(Employee_Master!P12,"")="Weekly",4.33,IF(IFERROR(Employee_Master!P12,"")="Monthly",1,IF(Payroll_Register!$K$3="Every Period",2,1)))),0) -> 0 | I14: =IFERROR(IF(D14=0,0,MIN(D14*0.02,200)*IF(IFERROR(Employee_Master!P12,"")<>"Semi-Monthly",1,IF(Payroll_Register!$K$3="Every Period",1,IF(Payroll_Register!$K$3="1st Half",IF(Payroll_Register!$C$3="1st Half",1,0),IF(Payroll_Register!$C$3="2nd Half",1,0))))/IF(IFERROR(Employee_Master!P12,"")="Weekly",4.33,IF(IFERROR(Employee_Master!P12,"")="Monthly",1,IF(Payroll_Register!$K$3="Every Period",2,1)))),0) -> 0 | J14: =IFERROR(Attendance_Register!Q15,0) -> 0 | K14: 0 | L14: =IFERROR(F14+Q14+S14+U14,0) -> 0 | M14: =IFERROR(G14+H14+I14+J14+K14+O14,0) -> 0 | N14: =IFERROR(L14-G14-H14-I14,0) -> 0 | O14: =IFERROR(IF(D14=0,0,IF(N14<=0,0,IF(N14*IF(IFERROR(Employee_Master!P12,"")="Weekly",0.5,IF(IFERROR(Employee_Master!P12,"")="Monthly",2,1))<=10416.67,0,IF(N14*IF(IFERROR(Employee_Master!P12,"")="Weekly",0.5,IF(IFERROR(Employee_Master!P12,"")="Monthly",2,1))<=16666.67,(N14*IF(IFERROR(Employee_Master!P12,"")="Weekly",0.5,IF(IFERROR(Employee_Master!P12,"")="Monthly",2,1))-10416.67)*0.15,IF(N14*IF(IFERROR(Employee_Master!P12,"")="Weekly",0.5,IF(IFERROR(Employee_Master!P12,"")="Monthly",2,1))<=33333.33,937.5+(N14*IF(IFERROR(Employee_Master!P12,"")="Weekly",0.5,IF(IFERROR(Employee_Master!P12,"")="Monthly",2,1))-16666.67)*0.2,IF(N14*IF(IFERROR(Employee_Master!P12,"")="Weekly",0.5,IF(IFERROR(Employee_Master!P12,"")="Monthly",2,1))<=83333.33,4270.83+(N14*IF(IFERROR(Employee_Master!P12,"")="Weekly",0.5,IF(IFERROR(Employee_Master!P12,"")="Monthly",2,1))-33333.33)*0.25,IF(N14*IF(IFERROR(Employee_Master!P12,"")="Weekly",0.5,IF(IFERROR(Employee_Master!P12,"")="Monthly",2,1))<=333333.33,16770.83+(N14*IF(IFERROR(Employee_Master!P12,"")="Weekly",0.5,IF(IFERROR(Employee_Master!P12,"")="Monthly",2,1))-83333.33)*0.3,91770.83+(N14*IF(IFERROR(Employee_Master!P12,"")="Weekly",0.5,IF(IFERROR(Employee_Master!P12,"")="Monthly",2,1))-333333.33)*0.35))))))/IF(IFERROR(Employee_Master!P12,"")="Weekly",0.5,IF(IFERROR(Employee_Master!P12,"")="Monthly",2,1))),0) -> 0 | P14: =IFERROR(IF(D14=0,0,D14/12/IF(IFERROR(Employee_Master!P12,"")="Weekly",4.33,IF(IFERROR(Employee_Master!P12,"")="Monthly",1,2))),0) -> 0 | Q14: 0 | R14: 0 | S14: =IFERROR(Employee_Master!I12*R14*2,0) -> 0 | T14: 0 | U14: =IFERROR(Employee_Master!I12*T14*0.3,0) -> 0 | V14: =IFERROR(L14-M14,0) -> 0 | W14: =IFERROR(IF(D14=0,0,VLOOKUP(D14,SSS_Table!$B$4:$E$64,4,TRUE())*IF(IFERROR(Employee_Master!P12,"")<>"Semi-Monthly",1,IF(Payroll_Register!$K$3="Every Period",1,IF(Payroll_Register!$K$3="1st Half",IF(Payroll_Register!$C$3="1st Half",1,0),IF(Payroll_Register!$C$3="2nd Half",1,0))))/IF(IFERROR(Employee_Master!P12,"")="Weekly",4.33,IF(IFERROR(Employee_Master!P12,"")="Monthly",1,IF(Payroll_Register!$K$3="Every Period",2,1)))),0) -> 0 | X14: =IFERROR(H14,0) -> 0 | Y14: =IFERROR(I14,0) -> 0 | Z14: =IFERROR(W14+X14+Y14,0) -> 0
A15: 10 | B15: =Employee_Master!B13 -> EMP-010 | C15: =Employee_Master!C13 -> 0 | D15: =Employee_Master!H13 -> 0 | E15: =IFERROR(IF(IFERROR(Employee_Master!P13,"")="Weekly",5,IF(IFERROR(Employee_Master!P13,"")="Monthly",22,11)),0) -> 11 | F15: =IFERROR(Employee_Master!I13*E15,0) -> 0 | G15: =IFERROR(IF(D15=0,0,VLOOKUP(D15,SSS_Table!$B$4:$D$64,3,TRUE())*IF(IFERROR(Employee_Master!P13,"")<>"Semi-Monthly",1,IF(Payroll_Register!$K$3="Every Period",1,IF(Payroll_Register!$K$3="1st Half",IF(Payroll_Register!$C$3="1st Half",1,0),IF(Payroll_Register!$C$3="2nd Half",1,0))))/IF(IFERROR(Employee_Master!P13,"")="Weekly",4.33,IF(IFERROR(Employee_Master!P13,"")="Monthly",1,IF(Payroll_Register!$K$3="Every Period",2,1)))),0) -> 0 | H15: =IFERROR(IF(D15=0,0,MIN(MAX(D15*0.025,250),2500)*IF(IFERROR(Employee_Master!P13,"")<>"Semi-Monthly",1,IF(Payroll_Register!$K$3="Every Period",1,IF(Payroll_Register!$K$3="1st Half",IF(Payroll_Register!$C$3="1st Half",1,0),IF(Payroll_Register!$C$3="2nd Half",1,0))))/IF(IFERROR(Employee_Master!P13,"")="Weekly",4.33,IF(IFERROR(Employee_Master!P13,"")="Monthly",1,IF(Payroll_Register!$K$3="Every Period",2,1)))),0) -> 0 | I15: =IFERROR(IF(D15=0,0,MIN(D15*0.02,200)*IF(IFERROR(Employee_Master!P13,"")<>"Semi-Monthly",1,IF(Payroll_Register!$K$3="Every Period",1,IF(Payroll_Register!$K$3="1st Half",IF(Payroll_Register!$C$3="1st Half",1,0),IF(Payroll_Register!$C$3="2nd Half",1,0))))/IF(IFERROR(Employee_Master!P13,"")="Weekly",4.33,IF(IFERROR(Employee_Master!P13,"")="Monthly",1,IF(Payroll_Register!$K$3="Every Period",2,1)))),0) -> 0 | J15: =IFERROR(Attendance_Register!Q16,0) -> 0 | K15: 0 | L15: =IFERROR(F15+Q15+S15+U15,0) -> 0 | M15: =IFERROR(G15+H15+I15+J15+K15+O15,0) -> 0 | N15: =IFERROR(L15-G15-H15-I15,0) -> 0 | O15: =IFERROR(IF(D15=0,0,IF(N15<=0,0,IF(N15*IF(IFERROR(Employee_Master!P13,"")="Weekly",0.5,IF(IFERROR(Employee_Master!P13,"")="Monthly",2,1))<=10416.67,0,IF(N15*IF(IFERROR(Employee_Master!P13,"")="Weekly",0.5,IF(IFERROR(Employee_Master!P13,"")="Monthly",2,1))<=16666.67,(N15*IF(IFERROR(Employee_Master!P13,"")="Weekly",0.5,IF(IFERROR(Employee_Master!P13,"")="Monthly",2,1))-10416.67)*0.15,IF(N15*IF(IFERROR(Employee_Master!P13,"")="Weekly",0.5,IF(IFERROR(Employee_Master!P13,"")="Monthly",2,1))<=33333.33,937.5+(N15*IF(IFERROR(Employee_Master!P13,"")="Weekly",0.5,IF(IFERROR(Employee_Master!P13,"")="Monthly",2,1))-16666.67)*0.2,IF(N15*IF(IFERROR(Employee_Master!P13,"")="Weekly",0.5,IF(IFERROR(Employee_Master!P13,"")="Monthly",2,1))<=83333.33,4270.83+(N15*IF(IFERROR(Employee_Master!P13,"")="Weekly",0.5,IF(IFERROR(Employee_Master!P13,"")="Monthly",2,1))-33333.33)*0.25,IF(N15*IF(IFERROR(Employee_Master!P13,"")="Weekly",0.5,IF(IFERROR(Employee_Master!P13,"")="Monthly",2,1))<=333333.33,16770.83+(N15*IF(IFERROR(Employee_Master!P13,"")="Weekly",0.5,IF(IFERROR(Employee_Master!P13,"")="Monthly",2,1))-83333.33)*0.3,91770.83+(N15*IF(IFERROR(Employee_Master!P13,"")="Weekly",0.5,IF(IFERROR(Employee_Master!P13,"")="Monthly",2,1))-333333.33)*0.35))))))/IF(IFERROR(Employee_Master!P13,"")="Weekly",0.5,IF(IFERROR(Employee_Master!P13,"")="Monthly",2,1))),0) -> 0 | P15: =IFERROR(IF(D15=0,0,D15/12/IF(IFERROR(Employee_Master!P13,"")="Weekly",4.33,IF(IFERROR(Employee_Master!P13,"")="Monthly",1,2))),0) -> 0 | Q15: 0 | R15: 0 | S15: =IFERROR(Employee_Master!I13*R15*2,0) -> 0 | T15: 0 | U15: =IFERROR(Employee_Master!I13*T15*0.3,0) -> 0 | V15: =IFERROR(L15-M15,0) -> 0 | W15: =IFERROR(IF(D15=0,0,VLOOKUP(D15,SSS_Table!$B$4:$E$64,4,TRUE())*IF(IFERROR(Employee_Master!P13,"")<>"Semi-Monthly",1,IF(Payroll_Register!$K$3="Every Period",1,IF(Payroll_Register!$K$3="1st Half",IF(Payroll_Register!$C$3="1st Half",1,0),IF(Payroll_Register!$C$3="2nd Half",1,0))))/IF(IFERROR(Employee_Master!P13,"")="Weekly",4.33,IF(IFERROR(Employee_Master!P13,"")="Monthly",1,IF(Payroll_Register!$K$3="Every Period",2,1)))),0) -> 0 | X15: =IFERROR(H15,0) -> 0 | Y15: =IFERROR(I15,0) -> 0 | Z15: =IFERROR(W15+X15+Y15,0) -> 0
